#usda 1.0
(
    customLayerData = {
        dictionary cameraSettings = {
            dictionary Front = {
                double3 position = (5, 0, 0)
                double radius = 5
            }
            dictionary Perspective = {
                double3 position = (0.09782872364005882, 0.8569621460885157, 0.3237141927645008)
                double3 target = (0.0002110361233517849, -0.6835920455730302, 0.007466956571319183)
            }
            dictionary Right = {
                double3 position = (0, -5, 0)
                double radius = 5
            }
            dictionary Top = {
                double3 position = (0, 0, 5)
                double radius = 5
            }
            string boundCamera = "/OmniverseKit_Persp"
        }
        dictionary metricsAssembler = {
            dictionary "/World/bl_calf" = {
            }
            dictionary "/World/bl_shoulder" = {
            }
            dictionary "/World/bl_thigh" = {
            }
            dictionary "/World/body" = {
            }
            dictionary "/World/br_shoulder" = {
            }
            dictionary "/World/br_thigh" = {
            }
            dictionary "/World/fl_calf" = {
            }
            dictionary "/World/fl_knee" = {
            }
            dictionary "/World/fl_shoulder" = {
            }
            dictionary "/World/fl_thigh" = {
            }
            dictionary "/World/fr_calf" = {
            }
            dictionary "/World/fr_shoulder" = {
            }
            dictionary "/World/fr_thigh" = {
            }
            dictionary "/World/left_calf" = {
            }
            dictionary "/World/left_knee" = {
            }
            dictionary "/World/left_shoulder" = {
            }
            dictionary "/World/left_shoulder_01" = {
            }
            dictionary "/World/left_thigh" = {
            }
            dictionary "/World/right_calf" = {
            }
            dictionary "/World/right_shoulder" = {
            }
            dictionary "/World/right_shoulder_01" = {
            }
            dictionary "/World/right_thigh" = {
            }
            int version = 1
        }
        dictionary omni_layer = {
            string authoring_layer = "./harold_8.usd"
            dictionary locked = {
            }
            dictionary muteness = {
            }
        }
        dictionary renderSettings = {
        }
    }
    defaultPrim = "Harold"
    endTimeCode = 1000000
    metersPerUnit = 1
    startTimeCode = 0
    timeCodesPerSecond = 60
    upAxis = "Z"
)

def Xform "Environment"
{
    quatd xformOp:orient = (1, 0, 0, 0)
    double3 xformOp:scale = (1, 1, 1)
    double3 xformOp:translate = (0, 0, 0)
    uniform token[] xformOpOrder = ["xformOp:translate", "xformOp:orient", "xformOp:scale"]

    def DistantLight "defaultLight" (
        prepend apiSchemas = ["ShapingAPI"]
    )
    {
        float inputs:angle = 1
        float inputs:intensity = 3000
        float inputs:shaping:cone:angle = 180
        float inputs:shaping:cone:softness
        float inputs:shaping:focus
        color3f inputs:shaping:focusTint
        asset inputs:shaping:ies:file
        quatd xformOp:orient = (0.6532814824381883, 0.2705980500730985, 0.27059805007309845, 0.6532814824381882)
        double3 xformOp:scale = (1, 1, 1)
        double3 xformOp:translate = (0, 0, 0)
        uniform token[] xformOpOrder = ["xformOp:translate", "xformOp:orient", "xformOp:scale"]
    }

    def DistantLight "DistantLight" (
        prepend apiSchemas = ["ShapingAPI"]
    )
    {
        float inputs:angle = 1
        float inputs:intensity = 3000
        float inputs:shaping:cone:angle = 180
        float inputs:shaping:cone:softness
        float inputs:shaping:focus
        color3f inputs:shaping:focusTint
        asset inputs:shaping:ies:file
        quatd xformOp:orient = (0.3855956967917661, 0.03834772218823334, 0.8635689504742392, 0.32263613963018384)
        double3 xformOp:scale = (1, 1, 1)
        double3 xformOp:translate = (-9.741157166251922e-31, 0.39970608805495605, 3.582996103629517e-31)
        uniform token[] xformOpOrder = ["xformOp:translate", "xformOp:orient", "xformOp:scale"]
    }
}

over "Render" (
    hide_in_stage_window = true
)
{
}

def Xform "Harold" (
    prepend apiSchemas = ["PhysicsArticulationRootAPI", "PhysxArticulationAPI"]
)
{
    quatf xformOp:orient = (1, 0, 0, 0)
    float3 xformOp:scale = (1, 1, 1)
    double3 xformOp:translate = (0, 0, 0.25575294205302257)
    uniform token[] xformOpOrder = ["xformOp:translate", "xformOp:orient", "xformOp:scale"]

    def "body" (
        prepend apiSchemas = ["PhysicsRigidBodyAPI", "PhysxRigidBodyAPI"]
        prepend payload = @./Corrected_Meshes/body.usd@
    )
    {
        bool physics:kinematicEnabled = 0
        bool physics:rigidBodyEnabled = 1
        quatf xformOp:orient = (1, 0, 0, 0)
        double xformOp:rotateX:unitsResolve = 0
        float3 xformOp:scale = (1, 1, 1)
        double3 xformOp:scale:unitsResolve = (1, 1, 1)
        double3 xformOp:translate = (0, 0, 0)
        uniform token[] xformOpOrder = ["xformOp:translate", "xformOp:orient", "xformOp:scale", "xformOp:rotateX:unitsResolve", "xformOp:scale:unitsResolve"]

        over "node_"
        {
            over "mesh_" (
                prepend apiSchemas = ["PhysicsCollisionAPI", "PhysxCollisionAPI", "PhysxConvexHullCollisionAPI", "PhysicsMeshCollisionAPI"]
            )
            {
                uniform token physics:approximation = "convexHull"
                bool physics:collisionEnabled = 1
            }
        }

        over "Looks"
        {
            over "DefaultMaterial" (
                prepend apiSchemas = ["PhysicsMaterialAPI"]
            )
            {
                float physics:density = 1000
                float physics:dynamicFriction = 1
                float physics:staticFriction = 1
            }
        }
    }

    def "fl_shoulder" (
        prepend apiSchemas = ["PhysicsRigidBodyAPI", "PhysxRigidBodyAPI"]
        prepend payload = @./Corrected_Meshes/left_shoulder/left_shoulder.usd@
    )
    {
        bool physics:kinematicEnabled = 0
        bool physics:rigidBodyEnabled = 1
        quatf xformOp:orient = (1, 0, 0, 0)
        double xformOp:rotateX:unitsResolve = 0
        float3 xformOp:scale = (1, 1, 1)
        double3 xformOp:scale:unitsResolve = (1, 1, 1)
        double3 xformOp:translate = (0.1855, 0.0479, 0.017695250259994712)
        uniform token[] xformOpOrder = ["xformOp:translate", "xformOp:orient", "xformOp:scale", "xformOp:rotateX:unitsResolve", "xformOp:scale:unitsResolve"]

        def PhysicsRevoluteJoint "fl_shoulder_joint" (
            prepend apiSchemas = ["PhysicsDriveAPI:angular"]
        )
        {
            uniform token physics:axis = "X"
            rel physics:body0 = </Harold/body>
            rel physics:body1 = </Harold/fl_shoulder>
            float physics:breakForce = inf
            float physics:breakTorque = inf
            point3f physics:localPos0 = (0.1855, 0.0479, 0.01769525)
            point3f physics:localPos1 = (0, 0, 0)
            quatf physics:localRot0 = (1, 0, 0, 0)
            quatf physics:localRot1 = (1, 0, 0, 0)
            float physics:lowerLimit = -90
            float physics:upperLimit = 90
        }

        over "node_"
        {
            over "mesh_" (
                prepend apiSchemas = ["PhysicsCollisionAPI", "PhysxCollisionAPI", "PhysxConvexHullCollisionAPI", "PhysicsMeshCollisionAPI"]
            )
            {
                uniform token physics:approximation = "convexHull"
                bool physics:collisionEnabled = 1
            }
        }

        over "Looks"
        {
            over "DefaultMaterial" (
                prepend apiSchemas = ["PhysicsMaterialAPI"]
            )
            {
                float physics:density = 380
                float physics:dynamicFriction = 1
                float physics:staticFriction = 1
            }
        }
    }

    def "fl_thigh" (
        prepend apiSchemas = ["PhysicsRigidBodyAPI", "PhysxRigidBodyAPI"]
        prepend payload = @./Corrected_Meshes/left_thigh.usd@
    )
    {
        bool physics:kinematicEnabled = 0
        bool physics:rigidBodyEnabled = 1
        quatf xformOp:orient = (1, 0, 0, 0)
        double xformOp:rotateX:unitsResolve = 0
        float3 xformOp:scale = (1, 1, 1)
        double3 xformOp:scale:unitsResolve = (1, 1, 1)
        double3 xformOp:translate = (0.2085, 0.064, 0.0291)
        uniform token[] xformOpOrder = ["xformOp:translate", "xformOp:orient", "xformOp:scale", "xformOp:rotateX:unitsResolve", "xformOp:scale:unitsResolve"]

        def PhysicsRevoluteJoint "fl_thigh_joint" (
            prepend apiSchemas = ["PhysicsDriveAPI:angular"]
        )
        {
            uniform token physics:axis = "Y"
            rel physics:body0 = </Harold/fl_shoulder>
            rel physics:body1 = </Harold/fl_thigh>
            float physics:breakForce = inf
            float physics:breakTorque = inf
            point3f physics:localPos0 = (0.022999998, 0.016100002, 0.011404751)
            point3f physics:localPos1 = (0, 0, 0)
            quatf physics:localRot0 = (1, 0, 0, 0)
            quatf physics:localRot1 = (1, 0, 0, 0)
            float physics:lowerLimit = -90
            float physics:upperLimit = 90
        }

        over "node_"
        {
            over "mesh_" (
                prepend apiSchemas = ["PhysicsCollisionAPI", "PhysxCollisionAPI", "PhysxConvexHullCollisionAPI", "PhysicsMeshCollisionAPI"]
            )
            {
                uniform token physics:approximation = "convexHull"
                bool physics:collisionEnabled = 1
            }
        }

        over "Looks"
        {
            over "DefaultMaterial" (
                prepend apiSchemas = ["PhysicsMaterialAPI"]
            )
            {
                float physics:density = 375
                float physics:dynamicFriction = 1
                float physics:staticFriction = 1
            }
        }
    }

    def "fl_calf" (
        prepend apiSchemas = ["PhysicsRigidBodyAPI", "PhysxRigidBodyAPI"]
        prepend payload = @./Corrected_Meshes/left_calf.usd@
    )
    {
        bool physics:kinematicEnabled = 0
        bool physics:rigidBodyEnabled = 1
        quatf xformOp:orient = (1, 0, 0, 0)
        double xformOp:rotateX:unitsResolve = 0
        float3 xformOp:scale = (1, 1, 1)
        double3 xformOp:scale:unitsResolve = (1, 1, 1)
        double3 xformOp:translate = (0.2059, 0.0632, -0.074)
        uniform token[] xformOpOrder = ["xformOp:translate", "xformOp:orient", "xformOp:scale", "xformOp:rotateX:unitsResolve", "xformOp:scale:unitsResolve"]

        def PhysicsRevoluteJoint "fl_calf_joint" (
            prepend apiSchemas = ["PhysicsDriveAPI:angular"]
        )
        {
            uniform token physics:axis = "Y"
            rel physics:body0 = </Harold/fl_thigh>
            rel physics:body1 = </Harold/fl_calf>
            float physics:breakForce = inf
            float physics:breakTorque = inf
            point3f physics:localPos0 = (-0.0026000014, -0.00080000306, -0.1031)
            point3f physics:localPos1 = (0, 0, 0)
            quatf physics:localRot0 = (1, 0, 0, 0)
            quatf physics:localRot1 = (1, 0, 0, 0)
            float physics:lowerLimit = -90
            float physics:upperLimit = 90
        }

        over "node_"
        {
            over "mesh_" (
                prepend apiSchemas = ["PhysicsCollisionAPI", "PhysxCollisionAPI", "PhysxConvexHullCollisionAPI", "PhysicsMeshCollisionAPI"]
            )
            {
                uniform token physics:approximation = "convexHull"
                bool physics:collisionEnabled = 1
            }
        }

        over "Looks"
        {
            over "DefaultMaterial" (
                prepend apiSchemas = ["PhysicsMaterialAPI"]
            )
            {
                float physics:density = 550
                float physics:dynamicFriction = 1
                float physics:staticFriction = 1
            }
        }
    }

    def "fr_shoulder" (
        prepend apiSchemas = ["PhysicsRigidBodyAPI", "PhysxRigidBodyAPI"]
        prepend payload = @./Corrected_Meshes/right_shoulder.usd@
    )
    {
        bool physics:kinematicEnabled = 0
        bool physics:rigidBodyEnabled = 1
        quatf xformOp:orient = (1, 0, 0, 0)
        double xformOp:rotateX:unitsResolve = 0
        float3 xformOp:scale = (1, 1, 1)
        double3 xformOp:scale:unitsResolve = (1, 1, 1)
        double3 xformOp:translate = (0.1855, -0.0479, 0.0177)
        uniform token[] xformOpOrder = ["xformOp:translate", "xformOp:orient", "xformOp:scale", "xformOp:rotateX:unitsResolve", "xformOp:scale:unitsResolve"]

        def PhysicsRevoluteJoint "fr_shoulder_joint" (
            prepend apiSchemas = ["PhysicsDriveAPI:angular"]
        )
        {
            uniform token physics:axis = "X"
            rel physics:body0 = </Harold/body>
            rel physics:body1 = </Harold/fr_shoulder>
            float physics:breakForce = inf
            float physics:breakTorque = inf
            point3f physics:localPos0 = (0.1855, -0.0479, 0.0177)
            point3f physics:localPos1 = (0, 0, 0)
            quatf physics:localRot0 = (1, 0, 0, 0)
            quatf physics:localRot1 = (1, 0, 0, 0)
            float physics:lowerLimit = -90
            float physics:upperLimit = 90
        }

        over "node_"
        {
            over "mesh_" (
                prepend apiSchemas = ["PhysicsCollisionAPI", "PhysxCollisionAPI", "PhysxConvexHullCollisionAPI", "PhysicsMeshCollisionAPI"]
            )
            {
                uniform token physics:approximation = "convexHull"
                bool physics:collisionEnabled = 1
            }
        }

        over "Looks"
        {
            over "DefaultMaterial" (
                prepend apiSchemas = ["PhysicsMaterialAPI"]
            )
            {
                float physics:density = 380
                float physics:dynamicFriction = 1
                float physics:staticFriction = 1
            }
        }
    }

    def "fr_thigh" (
        prepend apiSchemas = ["PhysicsRigidBodyAPI", "PhysxRigidBodyAPI"]
        prepend payload = @./Corrected_Meshes/right_thigh.usd@
    )
    {
        bool physics:kinematicEnabled = 0
        bool physics:rigidBodyEnabled = 1
        quatf xformOp:orient = (1, 0, 0, 0)
        double xformOp:rotateX:unitsResolve = 0
        float3 xformOp:scale = (1, 1, 1)
        double3 xformOp:scale:unitsResolve = (1, 1, 1)
        double3 xformOp:translate = (0.2085, -0.064, 0.0291)
        uniform token[] xformOpOrder = ["xformOp:translate", "xformOp:orient", "xformOp:scale", "xformOp:rotateX:unitsResolve", "xformOp:scale:unitsResolve"]

        def PhysicsRevoluteJoint "fr_thigh_joint" (
            prepend apiSchemas = ["PhysicsDriveAPI:angular"]
        )
        {
            uniform token physics:axis = "Y"
            rel physics:body0 = </Harold/fr_shoulder>
            rel physics:body1 = </Harold/fr_thigh>
            float physics:breakForce = inf
            float physics:breakTorque = inf
            point3f physics:localPos0 = (0.022999998, -0.016100002, 0.011400001)
            point3f physics:localPos1 = (0, 0, 0)
            quatf physics:localRot0 = (1, 0, 0, 0)
            quatf physics:localRot1 = (1, 0, 0, 0)
            float physics:lowerLimit = -90
            float physics:upperLimit = 90
        }

        over "node_"
        {
            over "mesh_" (
                prepend apiSchemas = ["PhysicsCollisionAPI", "PhysxCollisionAPI", "PhysxConvexHullCollisionAPI", "PhysicsMeshCollisionAPI"]
            )
            {
                uniform token physics:approximation = "convexHull"
                bool physics:collisionEnabled = 1
            }
        }

        over "Looks"
        {
            over "DefaultMaterial" (
                prepend apiSchemas = ["PhysicsMaterialAPI"]
            )
            {
                float physics:density = 375
                float physics:dynamicFriction = 1
                float physics:staticFriction = 1
            }
        }
    }

    def "fr_calf" (
        prepend apiSchemas = ["PhysicsRigidBodyAPI", "PhysxRigidBodyAPI"]
        prepend payload = @./Corrected_Meshes/right_calf.usd@
    )
    {
        bool physics:kinematicEnabled = 0
        bool physics:rigidBodyEnabled = 1
        quatf xformOp:orient = (1, 0, 0, 0)
        double xformOp:rotateX:unitsResolve = 0
        float3 xformOp:scale = (1, 1, 1)
        double3 xformOp:scale:unitsResolve = (1, 1, 1)
        double3 xformOp:translate = (0.2059, -0.0632, -0.074)
        uniform token[] xformOpOrder = ["xformOp:translate", "xformOp:orient", "xformOp:scale", "xformOp:rotateX:unitsResolve", "xformOp:scale:unitsResolve"]

        def PhysicsRevoluteJoint "fr_calf_joint" (
            prepend apiSchemas = ["PhysicsDriveAPI:angular"]
        )
        {
            uniform token physics:axis = "Y"
            rel physics:body0 = </Harold/fr_thigh>
            rel physics:body1 = </Harold/fr_calf>
            float physics:breakForce = inf
            float physics:breakTorque = inf
            point3f physics:localPos0 = (-0.0026000014, 0.00080000306, -0.1031)
            point3f physics:localPos1 = (0, 0, 0)
            quatf physics:localRot0 = (1, 0, 0, 0)
            quatf physics:localRot1 = (1, 0, 0, 0)
            float physics:lowerLimit = -90
            float physics:upperLimit = 90
        }

        over "node_"
        {
            over "mesh_" (
                prepend apiSchemas = ["PhysicsCollisionAPI", "PhysxCollisionAPI", "PhysxConvexHullCollisionAPI", "PhysicsMeshCollisionAPI"]
            )
            {
                uniform token physics:approximation = "convexHull"
                bool physics:collisionEnabled = 1
            }
        }

        over "Looks"
        {
            over "DefaultMaterial" (
                prepend apiSchemas = ["PhysicsMaterialAPI"]
            )
            {
                float physics:density = 550
                float physics:dynamicFriction = 1
                float physics:staticFriction = 1
            }
        }
    }

    def "bl_shoulder" (
        prepend apiSchemas = ["PhysicsRigidBodyAPI", "PhysxRigidBodyAPI"]
        prepend payload = @./Corrected_Meshes/left_shoulder.usd@
    )
    {
        bool physics:kinematicEnabled = 0
        bool physics:rigidBodyEnabled = 1
        quatf xformOp:orient = (1, 0, 0, 0)
        double xformOp:rotateX:unitsResolve = 0
        float3 xformOp:scale = (1, 1, 1)
        double3 xformOp:scale:unitsResolve = (1, 1, 1)
        double3 xformOp:translate = (-0.2308, 0.0479, 0.0177)
        uniform token[] xformOpOrder = ["xformOp:translate", "xformOp:orient", "xformOp:scale", "xformOp:rotateX:unitsResolve", "xformOp:scale:unitsResolve"]

        def PhysicsRevoluteJoint "bl_shoulder_joint" (
            prepend apiSchemas = ["PhysicsDriveAPI:angular"]
        )
        {
            uniform token physics:axis = "X"
            rel physics:body0 = </Harold/body>
            rel physics:body1 = </Harold/bl_shoulder>
            float physics:breakForce = inf
            float physics:breakTorque = inf
            point3f physics:localPos0 = (-0.2308, 0.0479, 0.0177)
            point3f physics:localPos1 = (0, 0, 0)
            quatf physics:localRot0 = (1, 0, 0, 0)
            quatf physics:localRot1 = (1, 0, 0, 0)
            float physics:lowerLimit = -90
            float physics:upperLimit = 90
        }

        over "node_"
        {
            over "mesh_" (
                prepend apiSchemas = ["PhysicsCollisionAPI", "PhysxCollisionAPI", "PhysxConvexHullCollisionAPI", "PhysicsMeshCollisionAPI"]
            )
            {
                uniform token physics:approximation = "convexHull"
                bool physics:collisionEnabled = 1
            }
        }

        over "Looks"
        {
            over "DefaultMaterial" (
                prepend apiSchemas = ["PhysicsMaterialAPI"]
            )
            {
                float physics:density = 380
                float physics:dynamicFriction = 1
                float physics:staticFriction = 1
            }
        }
    }

    def "bl_thigh" (
        prepend apiSchemas = ["PhysicsRigidBodyAPI", "PhysxRigidBodyAPI"]
        prepend payload = @./Corrected_Meshes/left_thigh.usd@
    )
    {
        bool physics:kinematicEnabled = 0
        bool physics:rigidBodyEnabled = 1
        quatf xformOp:orient = (1, 0, 0, 0)
        double xformOp:rotateX:unitsResolve = 0
        float3 xformOp:scale = (1, 1, 1)
        double3 xformOp:scale:unitsResolve = (1, 1, 1)
        double3 xformOp:translate = (-0.2078, 0.064, 0.0291)
        uniform token[] xformOpOrder = ["xformOp:translate", "xformOp:orient", "xformOp:scale", "xformOp:rotateX:unitsResolve", "xformOp:scale:unitsResolve"]

        def PhysicsRevoluteJoint "bl_thigh_joint" (
            prepend apiSchemas = ["PhysicsDriveAPI:angular"]
        )
        {
            uniform token physics:axis = "Y"
            rel physics:body0 = </Harold/bl_shoulder>
            rel physics:body1 = </Harold/bl_thigh>
            float physics:breakForce = inf
            float physics:breakTorque = inf
            point3f physics:localPos0 = (0.022999998, 0.016100002, 0.011400001)
            point3f physics:localPos1 = (0, 0, 0)
            quatf physics:localRot0 = (1, 0, 0, 0)
            quatf physics:localRot1 = (1, 0, 0, 0)
            float physics:lowerLimit = -90
            float physics:upperLimit = 90
        }

        over "node_"
        {
            over "mesh_" (
                prepend apiSchemas = ["PhysicsCollisionAPI", "PhysxCollisionAPI", "PhysxConvexHullCollisionAPI", "PhysicsMeshCollisionAPI"]
            )
            {
                uniform token physics:approximation = "convexHull"
                bool physics:collisionEnabled = 1
            }
        }

        over "Looks"
        {
            over "DefaultMaterial" (
                prepend apiSchemas = ["PhysicsMaterialAPI"]
            )
            {
                float physics:density = 375
                float physics:dynamicFriction = 1
                float physics:staticFriction = 1
            }
        }
    }

    def "bl_calf" (
        prepend apiSchemas = ["PhysicsRigidBodyAPI", "PhysxRigidBodyAPI"]
        prepend payload = @./Corrected_Meshes/left_calf.usd@
    )
    {
        bool physics:kinematicEnabled = 0
        bool physics:rigidBodyEnabled = 1
        quatf xformOp:orient = (1, 0, 0, 0)
        double xformOp:rotateX:unitsResolve = 0
        float3 xformOp:scale = (1, 1, 1)
        double3 xformOp:scale:unitsResolve = (1, 1, 1)
        double3 xformOp:translate = (-0.2104, 0.0632, -0.074)
        uniform token[] xformOpOrder = ["xformOp:translate", "xformOp:orient", "xformOp:scale", "xformOp:rotateX:unitsResolve", "xformOp:scale:unitsResolve"]

        def PhysicsRevoluteJoint "bl_calf_joint" (
            prepend apiSchemas = ["PhysicsDriveAPI:angular"]
        )
        {
            uniform token physics:axis = "Y"
            rel physics:body0 = </Harold/bl_thigh>
            rel physics:body1 = </Harold/bl_calf>
            float physics:breakForce = inf
            float physics:breakTorque = inf
            point3f physics:localPos0 = (-0.0026000002, -0.00080000306, -0.1031)
            point3f physics:localPos1 = (0, 0, 0)
            quatf physics:localRot0 = (1, 0, 0, 0)
            quatf physics:localRot1 = (1, 0, 0, 0)
            float physics:lowerLimit = -90
            float physics:upperLimit = 90
        }

        over "node_"
        {
            over "mesh_" (
                prepend apiSchemas = ["PhysicsCollisionAPI", "PhysxCollisionAPI", "PhysxConvexHullCollisionAPI", "PhysicsMeshCollisionAPI"]
            )
            {
                uniform token physics:approximation = "convexHull"
                bool physics:collisionEnabled = 1
            }
        }

        over "Looks"
        {
            over "DefaultMaterial" (
                prepend apiSchemas = ["PhysicsMaterialAPI"]
            )
            {
                float physics:density = 550
                float physics:dynamicFriction = 1
                float physics:staticFriction = 1
            }
        }
    }

    def "br_shoulder" (
        prepend apiSchemas = ["PhysicsRigidBodyAPI", "PhysxRigidBodyAPI"]
        prepend payload = @./Corrected_Meshes/right_shoulder.usd@
    )
    {
        bool physics:kinematicEnabled = 0
        bool physics:rigidBodyEnabled = 1
        quatf xformOp:orient = (1, 0, 0, 0)
        double xformOp:rotateX:unitsResolve = 0
        float3 xformOp:scale = (1, 1, 1)
        double3 xformOp:scale:unitsResolve = (1, 1, 1)
        double3 xformOp:translate = (-0.2308, -0.0479, 0.0177)
        uniform token[] xformOpOrder = ["xformOp:translate", "xformOp:orient", "xformOp:scale", "xformOp:rotateX:unitsResolve", "xformOp:scale:unitsResolve"]

        def PhysicsRevoluteJoint "br_shoulder_joint" (
            prepend apiSchemas = ["PhysicsDriveAPI:angular"]
        )
        {
            uniform token physics:axis = "X"
            rel physics:body0 = </Harold/body>
            rel physics:body1 = </Harold/br_shoulder>
            float physics:breakForce = inf
            float physics:breakTorque = inf
            point3f physics:localPos0 = (-0.2308, -0.0479, 0.0177)
            point3f physics:localPos1 = (0, 0, 0)
            quatf physics:localRot0 = (1, 0, 0, 0)
            quatf physics:localRot1 = (1, 0, 0, 0)
            float physics:lowerLimit = -90
            float physics:upperLimit = 90
        }

        over "node_"
        {
            over "mesh_" (
                prepend apiSchemas = ["PhysicsCollisionAPI", "PhysxCollisionAPI", "PhysxConvexHullCollisionAPI", "PhysicsMeshCollisionAPI"]
            )
            {
                uniform token physics:approximation = "convexHull"
                bool physics:collisionEnabled = 1
            }
        }

        over "Looks"
        {
            over "DefaultMaterial" (
                prepend apiSchemas = ["PhysicsMaterialAPI"]
            )
            {
                float physics:density = 380
                float physics:dynamicFriction = 1
                float physics:staticFriction = 1
            }
        }
    }

    def "br_thigh" (
        prepend apiSchemas = ["PhysicsRigidBodyAPI", "PhysxRigidBodyAPI"]
        prepend payload = @./Corrected_Meshes/right_thigh.usd@
    )
    {
        bool physics:kinematicEnabled = 0
        bool physics:rigidBodyEnabled = 1
        quatf xformOp:orient = (1, 0, 0, 0)
        double xformOp:rotateX:unitsResolve = 0
        float3 xformOp:scale = (1, 1, 1)
        double3 xformOp:scale:unitsResolve = (1, 1, 1)
        double3 xformOp:translate = (-0.2078, -0.064, 0.0291)
        uniform token[] xformOpOrder = ["xformOp:translate", "xformOp:orient", "xformOp:scale", "xformOp:rotateX:unitsResolve", "xformOp:scale:unitsResolve"]

        def PhysicsRevoluteJoint "br_thigh_joint" (
            prepend apiSchemas = ["PhysicsDriveAPI:angular"]
        )
        {
            uniform token physics:axis = "Y"
            rel physics:body0 = </Harold/br_shoulder>
            rel physics:body1 = </Harold/br_thigh>
            float physics:breakForce = inf
            float physics:breakTorque = inf
            point3f physics:localPos0 = (0.022999998, -0.016100002, 0.011400001)
            point3f physics:localPos1 = (0, 0, 0)
            quatf physics:localRot0 = (1, 0, 0, 0)
            quatf physics:localRot1 = (1, 0, 0, 0)
            float physics:lowerLimit = -90
            float physics:upperLimit = 90
        }

        over "node_"
        {
            over "mesh_" (
                prepend apiSchemas = ["PhysicsCollisionAPI", "PhysxCollisionAPI", "PhysxConvexHullCollisionAPI", "PhysicsMeshCollisionAPI"]
            )
            {
                uniform token physics:approximation = "convexHull"
                bool physics:collisionEnabled = 1
            }
        }

        over "Looks"
        {
            over "DefaultMaterial" (
                prepend apiSchemas = ["PhysicsMaterialAPI"]
            )
            {
                float physics:density = 375
                float physics:dynamicFriction = 1
                float physics:staticFriction = 1
            }
        }
    }

    def "br_calf" (
        prepend apiSchemas = ["PhysicsRigidBodyAPI", "PhysxRigidBodyAPI", "MaterialBindingAPI"]
        prepend payload = @./Corrected_Meshes/right_calf.usd@
    )
    {
        rel material:binding = </Harold/br_calf/Looks/DefaultMaterial> (
            bindMaterialAs = "weakerThanDescendants"
        )
        bool physics:kinematicEnabled = 0
        bool physics:rigidBodyEnabled = 1
        quatf xformOp:orient = (1, 0, 0, 0)
        double xformOp:rotateX:unitsResolve = 0
        float3 xformOp:scale = (1, 1, 1)
        double3 xformOp:scale:unitsResolve = (1, 1, 1)
        double3 xformOp:translate = (-0.2104, -0.0632, -0.074)
        uniform token[] xformOpOrder = ["xformOp:translate", "xformOp:orient", "xformOp:scale", "xformOp:rotateX:unitsResolve", "xformOp:scale:unitsResolve"]

        def PhysicsRevoluteJoint "br_calf_joint" (
            prepend apiSchemas = ["PhysicsDriveAPI:angular"]
        )
        {
            uniform token physics:axis = "Y"
            rel physics:body0 = </Harold/br_thigh>
            rel physics:body1 = </Harold/br_calf>
            float physics:breakForce = inf
            float physics:breakTorque = inf
            point3f physics:localPos0 = (-0.0026000002, 0.00080000306, -0.1031)
            point3f physics:localPos1 = (0, 0, 0)
            quatf physics:localRot0 = (1, 0, 0, 0)
            quatf physics:localRot1 = (1, 0, 0, 0)
            float physics:lowerLimit = -90
            float physics:upperLimit = 90
        }

        over "node_" (
            prepend apiSchemas = ["MaterialBindingAPI"]
        )
        {
            rel material:binding = </Harold/br_calf/Looks/DefaultMaterial> (
                bindMaterialAs = "weakerThanDescendants"
            )

            over "mesh_" (
                prepend apiSchemas = ["PhysicsCollisionAPI", "PhysxCollisionAPI", "PhysxConvexHullCollisionAPI", "PhysicsMeshCollisionAPI", "MaterialBindingAPI"]
            )
            {
                rel material:binding = </Harold/br_calf/Looks/DefaultMaterial> (
                    bindMaterialAs = "weakerThanDescendants"
                )
                uniform token physics:approximation = "convexHull"
                bool physics:collisionEnabled = 1
            }
        }

        over "Looks"
        {
            over "DefaultMaterial" (
                prepend apiSchemas = ["PhysicsMaterialAPI"]
            )
            {
                float physics:density = 550
                float physics:dynamicFriction = 1
                float physics:staticFriction = 1
                uniform token ui:nodegraph:node:expansionState = "open"

                over "DefaultMaterial"
                {
                    uniform token ui:nodegraph:node:expansionState = "open"
                }
            }
        }
    }
}

def Xform "GroundPlane" (
    prepend apiSchemas = ["MaterialBindingAPI"]
)
{
    rel material:binding = </Harold/Looks/OmniSurface> (
        bindMaterialAs = "weakerThanDescendants"
    )
    quatf xformOp:orient = (1, 0, 0, 0)
    float3 xformOp:scale = (1, 1, 1)
    double3 xformOp:translate = (0, 0, 0)
    uniform token[] xformOpOrder = ["xformOp:translate", "xformOp:orient", "xformOp:scale"]

    def Mesh "CollisionMesh"
    {
        uniform bool doubleSided = 0
        int[] faceVertexCounts = [4]
        int[] faceVertexIndices = [0, 1, 2, 3]
        normal3f[] normals = [(0, 0, 1), (0, 0, 1), (0, 0, 1), (0, 0, 1)]
        point3f[] points = [(-25, -25, 0), (25, -25, 0), (25, 25, 0), (-25, 25, 0)]
        color3f[] primvars:displayColor = [(0.5, 0.5, 0.5)]
        texCoord2f[] primvars:st = [(0, 0), (1, 0), (1, 1), (0, 1)] (
            interpolation = "varying"
        )
    }

    def Plane "CollisionPlane" (
        prepend apiSchemas = ["PhysicsCollisionAPI"]
    )
    {
        uniform token axis = "Z"
        uniform token purpose = "guide"
    }
}

